<robot name="gopher_torso">
  <link name="torso">
    <inertial>
      <origin rpy="0 0 0" xyz="0.0 0.0 00.0" />
      <mass value="10.0" />
      <inertia ixx="1.225" ixy="0.0099" ixz="0.0062" iyy="1.2853" iyz="-0.0034" izz="0.987" />
    </inertial>
    <visual>
      <origin rpy="0 0 0" xyz="0 0 0" />
      <geometry>
        <mesh filename="package://gopher_description/meshes/torso.STL" />
      </geometry>
      <material name="">
        <color rgba="0.3 0.3 0.5 1" />
      </material>
    </visual>
    <collision>
      <origin rpy="0 0 0" xyz="0 0 0" />
      <geometry>
        <mesh filename="package://gopher_description/meshes/torso.STL" />
      </geometry>
    </collision>
  </link>
  <link name="main_cam_support">
    <collision>
      <origin rpy="0 0 0" xyz="0 0 0.01"/>
      <geometry>
        <box size="0.08 0.08 0.02"/>
      </geometry>
    </collision>
    <visual>
      <origin rpy="0 0 0" xyz="0 0 0.01"/>
      <geometry>
        <box size="0.08 0.08 0.02"/>
      </geometry>
      <material name="">
        <color rgba="0.5 0.6 0.7 1"/>
      </material>
    </visual>
    <inertial>
      <origin rpy="0 0 0" xyz="0 0 0.01"/>
      <mass value="0.2"/>
      <inertia ixx="3.33333333333e-05" ixy="0.0" ixz="0.0" iyy="3.33333333333e-05" iyz="0.0" izz="5.33333333333e-05"/>
    </inertial>
  </link>
  <joint name="main_cam_support_joint" type="fixed">
    <parent link="torso"/>
    <child link="main_cam_support"/>
    <origin rpy="0 0 0" xyz="0.0 0.0 0.8"/>
    <axis xyz="0 0 1"/>
  </joint>
  <link name="main_cam_yaw_link">
    <collision>
      <origin rpy="0 0 0" xyz="0 0 0.02"/>
      <geometry>
        <box size="0.02 0.02 0.04"/>
      </geometry>
    </collision>
    <visual>
      <origin rpy="0 0 0" xyz="0 0 0.02"/>
      <geometry>
        <box size="0.02 0.02 0.04"/>
      </geometry>
      <material name="blue">
        <color rgba="0 0 1 1"/>
      </material>
    </visual>
    <inertial>
      <origin rpy="0 0 0" xyz="0 0 0.02"/>
      <mass value="0.5"/>
      <inertia ixx="7.9e-02" ixy="0.0" ixz="0.0" iyy="7.9e-02" iyz="0.0" izz="2.5e-02"/>
    </inertial>
  </link>
  <joint name="main_cam_yaw_joint" type="revolute">
    <parent link="main_cam_support"/>
    <child link="main_cam_yaw_link"/>
    <origin rpy="0 0 0" xyz="0 0 0.02"/>
    <axis xyz="0 0 1"/>
    <limit effort="20" lower="-1.047" upper="1.047" velocity="1.0"/>
  </joint>
  <link name="main_cam_pitch_link">
    <collision>
      <origin rpy="0 0 0" xyz="0.02 0 0"/>
      <geometry>
        <box size="0.04 0.02 0.02"/>
      </geometry>
    </collision>
    <visual>
      <origin rpy="0 0 0" xyz="0.02 0 0"/>
      <geometry>
        <box size="0.04 0.02 0.02"/>
      </geometry>
      <material name="red">
        <color rgba="1 0 0 1"/>
      </material>
    </visual>
    <inertial>
      <origin rpy="0 0 0" xyz="0 0 0"/>
      <mass value="0.5"/>
      <inertia ixx="7.9e-02" ixy="0.0" ixz="0.0" iyy="7.9e-02" iyz="0.0" izz="2.5e-02"/>
    </inertial>
  </link>
  <joint name="main_cam_pitch_joint" type="revolute">
    <parent link="main_cam_yaw_link"/>
    <child link="main_cam_pitch_link"/>
    <origin rpy="1.57 0 0" xyz="0.0 0.0 0.04"/>
    <axis xyz="0 0 1"/>
    <limit effort="20" lower="-1.047" upper="1.047" velocity="1.0"/>
  </joint>
  <material name="aluminum">
    <color rgba="0.5 0.5 0.5 1"/>
  </material>
</robot>
